<?xml version="1.0" ?>
<sdf version="1.9">
  <model name="load_250_v33">
    <link name="base_link">
      <inertial>
        <mass>0.0001</mass>
        <inertia>
          <ixx>1e-09</ixx>
          <ixy>0</ixy>
          <ixz>0</ixz>
          <iyy>1e-09</iyy>
          <iyz>0</iyz>
          <izz>1e-09</izz>
        </inertia>
      </inertial>
    </link>
    
    <link name="froller_1">
      <pose relative_to="__model__">0.175 0.0 -0.03 0.0 -0.0 0.0</pose>
      <inertial>
        <mass>0.2630560248605853</mass>
        <inertia>
          <ixx>4.20889639776937e-05</ixx>
          <ixy>0.0</ixy>
          <ixz>2.168404344971009e-19</ixz>
          <iyy>4.20889639776937e-05</iyy>
          <iyz>0.0</iyz>
          <izz>4.20889639776937e-05</izz>
        </inertia>
      </inertial>
      <visual name="froller_1__froller_visual">
        <geometry>
          <mesh>
            <scale>0.01 0.01 0.01</scale>
            <uri>meshes/froller_1/froller_visual.obj</uri>
          </mesh>
        </geometry>
      </visual>
      <collision name="froller_1__froller_collision">
        <pose relative_to="__model__">0.175 0.0 -0.03 -0.0 -1.5707963267948966 0</pose>
        <geometry>
          <sphere>
            <radius>0.02</radius>
          </sphere>
        </geometry>
        <surface>
          <friction>
            <torsional>
              <coefficient>0.0</coefficient>
            </torsional>
            <ode>
              <mu>0.0</mu>
              <mu2>0.0</mu2>
            </ode>
            <bullet>
              <friction>0.0</friction>
              <friction2>0.0</friction2>
              <rolling_friction>0.0</rolling_friction>
            </bullet>
          </friction>
        </surface>
      </collision>
    </link>
    <link name="imu_1">
      <pose relative_to="__model__">0.0 0.0 0.025 0.0 -0.0 0.0</pose>
      <inertial>
        <pose>0.0 0.0 0.010000000000000002 0.0 -0.0 0.0</pose>
        <mass>0.2355</mass>
        <inertia>
          <ixx>2.551249999999995e-05</ixx>
          <ixy>0.0</ixy>
          <ixz>0.0</ixz>
          <iyy>5.6912499999999954e-05</iyy>
          <iyz>0.0</iyz>
          <izz>6.672499999999997e-05</izz>
        </inertia>
      </inertial>
      <visual name="imu_1__imu_visual">
        <geometry>
          <mesh>
            <scale>0.01 0.01 0.01</scale>
            <uri>meshes/imu_1/imu_visual.obj</uri>
          </mesh>
        </geometry>
      </visual>
      <collision name="imu_1__imu_collision">
        <pose relative_to="__model__">0.0 0.0 0.035 -0.0 -1.5707963267948966 0</pose>
        <geometry>
          <box>
            <size>0.02 0.03 0.05</size>
          </box>
        </geometry>
      </collision>
    </link>
    <link name="broller_1">
      <pose relative_to="__model__">-0.175 0.0 -0.03 0.0 -0.0 0.0</pose>
      <inertial>
        <mass>0.2630560248605853</mass>
        <inertia>
          <ixx>4.20889639776937e-05</ixx>
          <ixy>0.0</ixy>
          <ixz>-2.168404344971009e-19</ixz>
          <iyy>4.20889639776937e-05</iyy>
          <iyz>0.0</iyz>
          <izz>4.20889639776937e-05</izz>
        </inertia>
      </inertial>
      <visual name="broller_1__broller_visual">
        <geometry>
          <mesh>
            <scale>0.01 0.01 0.01</scale>
            <uri>meshes/broller_1/broller_visual.obj</uri>
          </mesh>
        </geometry>
      </visual>
      <collision name="broller_1__broller_collision">
        <pose relative_to="__model__">-0.175 0.0 -0.03 -0.0 -1.5707963267948966 0</pose>
        <geometry>
          <box>
            <size>0.04 0.04 0.04</size>
          </box>
        </geometry>
        <surface>
          <friction>
            <torsional>
              <coefficient>0.0</coefficient>
            </torsional>
            <ode>
              <mu>0.0</mu>
              <mu2>0.0</mu2>
            </ode>
            <bullet>
              <friction>0.0</friction>
              <friction2>0.0</friction2>
              <rolling_friction>0.0</rolling_friction>
            </bullet>
          </friction>
        </surface>
      </collision>
    </link>
    <link name="platform_1">
      <pose relative_to="__model__">0.0 0.0 0.055 0.0 -0.0 6.123233995736766e-17</pose>
      <inertial>
        <pose>1.8256230444553304e-11 0.0 0.039618976470643864 0.0 -0.0 -6.123233995736766e-17</pose>
        <mass>11.533219999999998</mass>
        <inertia>
          <ixx>0.024765548801522416</ixx>
          <ixy>1.684427072887525e-11</ixy>
          <ixz>-5.238784181586978e-12</ixz>
          <iyy>0.05554422130152241</iyy>
          <iyz>1.448607473321317e-10</iyz>
          <izz>0.06986293283333335</izz>
        </inertia>
      </inertial>
      <visual name="platform_1__platform_visual">
        <geometry>
          <mesh>
            <scale>0.01 0.01 0.01</scale>
            <uri>meshes/platform_1/platform_visual.obj</uri>
          </mesh>
        </geometry>
      </visual>
      <collision name="platform_1__platform_collision">
        <pose relative_to="__model__">0.0 0.0 0.08850000629013424 -0.0 -1.5707963267948966 0</pose>
        <geometry>
          <box>
            <size>0.06700001258026848 0.21000000000000005 0.360000025160537</size>
          </box>
        </geometry>
      </collision>
    </link>
    <link name="camera_1">
      <pose relative_to="__model__">0.195 0.0 0.05199999999999999 0.0 -0.0 0.0</pose>
      <inertial>
        <pose>0.0 0.0 0.0025000000000000022 0.0 -0.0 0.0</pose>
        <mass>0.019624999999999997</mass>
        <inertia>
          <ixx>4.129427083333333e-06</ixx>
          <ixy>0.0</ixy>
          <ixz>0.0</ixz>
          <iyy>2.0442708333317638e-07</iyy>
          <iyz>0.0</iyz>
          <izz>4.252083333333343e-06</izz>
        </inertia>
      </inertial>
      <visual name="camera_1__camera_visual">
        <geometry>
          <mesh>
            <scale>0.01 0.01 0.01</scale>
            <uri>meshes/camera_1/camera_visual.obj</uri>
          </mesh>
        </geometry>
      </visual>
      <collision name="camera_1__camera_collision">
        <pose relative_to="__model__">0.195 0.0 0.05449999999999999 -0.0 -1.5707963267948966 0</pose>
        <geometry>
          <box>
            <size>0.005 0.05 0.01</size>
          </box>
        </geometry>
      </collision>
    </link>
    <link name="rwheel_1">
      <pose relative_to="__model__">0.0 -0.145 0.0 0.0 -0.0 1.0145104319789719e-51</pose>
      <inertial>
        <pose>-3.872152868763962e-07 -0.0050002387848986085 -5.898795480966115e-06 0.0 -0.0 -1.0145104319789719e-51</pose>
        <mass>1.0452977986041356</mass>
        <inertia>
          <ixx>0.0011276214981046917</ixx>
          <ixy>-3.9380700690467983e-10</ixy>
          <ixz>6.493558753287392e-08</ixz>
          <iyy>0.0019158393483540905</iyy>
          <iyz>-5.260724932004131e-09</iyz>
          <izz>0.0011276094071435289</izz>
        </inertia>
      </inertial>
      <visual name="rwheel_1__rwheel_visual">
        <geometry>
          <mesh>
            <scale>0.01 0.01 0.01</scale>
            <uri>meshes/rwheel_1/rwheel_visual.obj</uri>
          </mesh>
        </geometry>
      </visual>
      <collision name="rwheel_1__rwheel_collision">
        <pose relative_to="__model__">0.0 -0.15 0.0 -0.0 -1.5707963267948966 0</pose>
        <geometry>
          <sphere>
            <radius>0.05</radius>
          </sphere>
        </geometry>
        <surface>
          <friction>
            <torsional>
              <coefficient>0.0</coefficient>
            </torsional>
            <ode>
              <mu>0.8</mu>
              <mu2>0.8</mu2>
            </ode>
            <bullet>
              <friction>0.8</friction>
              <friction2>0.8</friction2>
              <rolling_friction>0.01</rolling_friction>
            </bullet>
          </friction>
        </surface>
      </collision>
    </link>
    <link name="flidar_1">
      <pose relative_to="__model__">0.15 -0.075 0.06199999999999999 0.0 -0.0 0.0</pose>
      <inertial>
        <pose>2.7755575615628914e-17 -1.3877787807814457e-17 0.0049999999999999975 0.0 -0.0 0.0</pose>
        <mass>0.1541343895667492</mass>
        <inertia>
          <ixx>2.536795161619306e-05</ixx>
          <ixy>-2.168404344971009e-19</ixy>
          <ixz>4.336808689942018e-19</ixz>
          <iyy>2.536795161619306e-05</iyy>
          <iyz>0.0</iyz>
          <izz>4.816699673960718e-05</izz>
        </inertia>
      </inertial>
      <visual name="flidar_1__flidar_visual">
        <geometry>
          <mesh>
            <scale>0.01 0.01 0.01</scale>
            <uri>meshes/flidar_1/flidar_visual.obj</uri>
          </mesh>
        </geometry>
      </visual>
      <collision name="flidar_1__flidar_collision">
        <pose relative_to="__model__">0.15 -0.075 0.06699999999999999 -0.0 -1.5707963267948966 0</pose>
        <geometry>
          <box>
            <size>0.01 0.05 0.05</size>
          </box>
        </geometry>
      </collision>
      <sensor name='gpu_lidar_1' type='gpu_lidar'>
        <pose>0.0 0.0 0.06699999999999999 0.0 -0.0 0.0</pose>
        <topic>scan</topic>
        <ignition_frame_id>load_250_v33/flidar_1</ignition_frame_id>
        <update_rate>10</update_rate>
        <lidar>
          <scan>
            <horizontal>
              <samples>270</samples>
              <resolution>1</resolution>
              <min_angle>-3.0</min_angle>
              <max_angle>1.396263</max_angle>
            </horizontal>
            <vertical>
              <samples>1</samples>
              <resolution>1</resolution>
              <min_angle>0.0</min_angle>
              <max_angle>0.0</max_angle>
            </vertical>
          </scan>
          <range>
            <min>0.1</min>
            <max>10.0</max>
            <resolution>0.01</resolution>
          </range>
        </lidar>
        <visualize>true</visualize>
      </sensor>
    </link>
    <link name="blidar_1">
      <pose relative_to="__model__">-0.15 0.075 0.06199999999999999 0.0 -0.0 0.0</pose>
      <inertial>
        <pose>0.0 0.0 0.0049999999999999975 0.0 -0.0 0.0</pose>
        <mass>0.15413438956674944</mass>
        <inertia>
          <ixx>2.536795161619306e-05</ixx>
          <ixy>0.0</ixy>
          <ixz>0.0</ixz>
          <iyy>2.5367951616194796e-05</iyy>
          <iyz>0.0</iyz>
          <izz>4.816699673960891e-05</izz>
        </inertia>
      </inertial>
      <visual name="blidar_1__blidar_visual">
        <geometry>
          <mesh>
            <scale>0.01 0.01 0.01</scale>
            <uri>meshes/blidar_1/blidar_visual.obj</uri>
          </mesh>
        </geometry>
      </visual>
      <collision name="blidar_1__blidar_collision">
        <pose relative_to="__model__">-0.15 0.075 0.06699999999999999 -0.0 -1.5707963267948966 0</pose>
        <geometry>
          <box>
            <size>0.01 0.05000000000000004 0.05000000000000002</size>
          </box>
        </geometry>
      </collision>
      <!-- <sensor name='gpu_lidar_2' type='gpu_lidar'>
        <pose>0.0 0.0 0.06699999999999999 0.0 -0.0 0.0</pose>
        <topic>scan</topic>
        <ignition_frame_id>load_250_v33/blidar_1</ignition_frame_id>
        <visualize>true</visualize>
        <update_rate>10</update_rate>
        <lidar>
          <scan>
            <horizontal>
              <samples>90</samples>
              <resolution>1</resolution>
              <min_angle>1.60</min_angle>
              <max_angle>3.14</max_angle>
            </horizontal>
            <vertical>
              <samples>1</samples>
              <resolution>1</resolution>
              <min_angle>0.0</min_angle>
              <max_angle>0.0</max_angle>
            </vertical>
          </scan>
          <range>
            <min>0.2</min>
            <max>10.0</max>
            <resolution>0.1</resolution>
          </range>
        </lidar>
      </sensor> -->
    </link>
    <link name="lwheel_1">
      <pose relative_to="__model__">0.0 0.145 0.0 -1.7931687772763235e-38 -0.0 -7.350647110176754e-36</pose>
      <inertial>
        <pose>-3.8721528699592e-07 0.0049997612151014 -5.898795481025863e-06 1.7931687772763235e-38 -1.3180950890745391e-73 7.350647110176754e-36</pose>
        <mass>1.0452977986041383</mass>
        <inertia>
          <ixx>0.0011276214981046986</ixx>
          <ixy>-3.938070089562201e-10</ixy>
          <ixz>6.493558752894794e-08</ixz>
          <iyy>0.0019158393483541083</iyy>
          <iyz>-5.260724930442202e-09</iyz>
          <izz>0.0011276094071435462</izz>
        </inertia>
      </inertial>
      <visual name="lwheel_1__lwheel_visual">
        <geometry>
          <mesh>
            <scale>0.01 0.01 0.01</scale>
            <uri>meshes/lwheel_1/lwheel_visual.obj</uri>
          </mesh>
        </geometry>
      </visual>
      <collision name="lwheel_1__lwheel_collision">
        <pose relative_to="__model__">0.0 0.15 0.0 -0.0 -1.5707963267948966 0</pose>
        <geometry>
          <sphere>
            <radius>0.05</radius>
          </sphere>
        </geometry>
        <surface>
          <friction>
            <torsional>
              <coefficient>0.0</coefficient>
            </torsional>
            <ode>
              <mu>0.8</mu>
              <mu2>0.8</mu2>
            </ode>
            <bullet>
              <friction>0.8</friction>
              <friction2>0.8</friction2>
              <rolling_friction>0.01</rolling_friction>
            </bullet>
          </friction>
        </surface>
      </collision>
    </link>
    <link name="main_body_1">
      <inertial>
        <pose>1.4462448403023515e-05 7.373652162995582e-17 0.03247477028451328 0.0 -0.0 0.0</pose>
        <mass>46.475965512430236</mass>
        <inertia>
          <ixx>0.2581412863064977</ixx>
          <ixy>0.004161628518543688</ixy>
          <ixz>-1.202255198884228e-05</ixz>
          <iyy>0.6234602310080568</iyy>
          <iyz>1.112902595487376e-16</iyz>
          <izz>0.820010763272547</izz>
        </inertia>
      </inertial>
      <visual name="main_body_1__main_body_visual">
        <geometry>
          <mesh>
            <scale>0.01 0.01 0.01</scale>
            <uri>meshes/main_body_1/main_body_visual.obj</uri>
          </mesh>
        </geometry>
      </visual>
      <collision name="main_body_1__main_body_collision">
        <pose relative_to="__model__">0.0 0.0 0.0425 -0.0 -1.5707963267948966 0</pose>
        <geometry>
          <box>
            <size>0.145 0.29 0.4</size>
          </box>
        </geometry>
      </collision>
    </link>
    <joint name="rigid_35" type="fixed">
      <pose relative_to="__model__">0.15 -0.075 0.06199999999999999 0.0 -0.0 0.0</pose>
      <parent>main_body_1</parent>
      <child>flidar_1</child>
      <axis/>
    </joint>
    <joint name="slider_36" type="prismatic">
      <pose relative_to="__model__">0.0 0.0 0.055 0.0 -0.0 0.0</pose>
      <parent>main_body_1</parent>
      <child>platform_1</child>
      <axis>
        <xyz expressed_in="__model__">0.0 0.0 1.0</xyz>
        <limit>
          <lower>0.0</lower>
          <upper>0.055</upper>
        </limit>
      </axis>
    </joint>
    <joint name="rigid_37" type="fixed">
      <pose relative_to="__model__">0.0 0.0 0.025 0.0 -0.0 0.0</pose>
      <parent>main_body_1</parent>
      <child>imu_1</child>
      <axis/>
    </joint>
    <joint name="rigid_38" type="fixed">
      <pose relative_to="__model__">-0.175 0.0 -0.03 0.0 -0.0 0.0</pose>
      <parent>main_body_1</parent>
      <child>broller_1</child>
      <axis/>
    </joint>
    <joint name="rigid_39" type="fixed">
      <pose relative_to="__model__">0.175 0.0 -0.03 0.0 -0.0 0.0</pose>
      <parent>main_body_1</parent>
      <child>froller_1</child>
      <axis/>
    </joint>
    <joint name="rigid_40" type="fixed">
      <pose relative_to="__model__">-0.15 0.075 0.06199999999999999 0.0 -0.0 0.0</pose>
      <parent>main_body_1</parent>
      <child>blidar_1</child>
      <axis/>
    </joint>
    <joint name="rigid_41" type="fixed">
      <pose relative_to="__model__">0.195 0.0 0.05199999999999999 0.0 -0.0 0.0</pose>
      <parent>main_body_1</parent>
      <child>camera_1</child>
      <axis/>
    </joint>
    <joint name="revolute_42" type="revolute">
      <pose relative_to="__model__">0.0 -0.145 0.0 0.0 -0.0 0.0</pose>
      <parent>main_body_1</parent>
      <child>rwheel_1</child>
      <axis>
        <xyz expressed_in="__model__">0.0 1.0 -0.0</xyz>
      </axis>
    </joint>
    <joint name="revolute_43" type="revolute">
      <pose relative_to="__model__">0.0 0.145 0.0 0.0 -0.0 0.0</pose>
      <parent>main_body_1</parent>
      <child>lwheel_1</child>
      <axis>
        <xyz expressed_in="__model__">0.0 1.0 -0.0</xyz>
      </axis>
    </joint>
    <joint name="base_link_joint" type="fixed">
      <parent>base_link</parent>
      <child>main_body_1</child>
      <axis/>
    </joint>
    <plugin
      filename="ignition-gazebo-diff-drive-system"
      name="ignition::gazebo::systems::DiffDrive">
      <left_joint>revolute_43</left_joint>
      <right_joint>revolute_42</right_joint>
      <wheel_separation>0.3</wheel_separation>
      <wheel_radius>0.05</wheel_radius>
      <odom_publish_frequency>30</odom_publish_frequency>
      <max_linear_acceleration>2</max_linear_acceleration>
      <min_linear_acceleration>-1</min_linear_acceleration>
      <max_angular_acceleration>4</max_angular_acceleration>
      <min_angular_acceleration>-4</min_angular_acceleration>
      <max_linear_velocity>2.0</max_linear_velocity>
      <min_linear_velocity>-0.5</min_linear_velocity>
      <max_angular_velocity>3</max_angular_velocity>
      <min_angular_velocity>-1</min_angular_velocity>
    </plugin>
  </model>
</sdf>
